ERROR:root:
Traceback (most recent call last):
  File "main.py", line 6, in <module>
    raise Exception
Exception
